<?xml version="1.0"?>
<robot name="object">
  <link name="base_link"> <!-- required name, will throw warning about node existence -->
    <inertial>
      <origin xyz="0 0 0" /> 
      <mass value="1.0" />
      <inertia  ixx="1.0" ixy="0.0"  ixz="0.0"  iyy="1.0"  iyz="0.0"  izz="1.0" />
    </inertial>
    <visual>
      <origin xyz="0 0 0"/>
    </visual>
    <collision>
      <origin xyz="0 0 0"/>
    </collision>
  </link> 
  
  <joint name="j_translation_x" type="prismatic">
    <parent link="base_link"/>
    <child link="l_one"/>
    <origin xyz="0 0 0" rpy="0 0 0"/>
    <axis xyz="1 0 0"/>
    <!--<limit lower="-100" upper="100" effort="1.0" velocity="1.0"/>--> <!-- long box -->
    <limit lower="-4" upper="13" effort="1.0" velocity="1.0"/>
  </joint>
  
  <link name="l_one"/> <!-- fake link, will throw warning about node existence -->
  
  <joint name="j_translation_y" type="prismatic">
    <parent link="l_one"/>
    <child link="true_base_link"/>
    <origin xyz="0 0 0" rpy="0 0 0"/>
    <axis xyz="0 1 0"/>
    <!--<limit lower="-8" upper="8" effort="1.0" velocity="1.0"/>--> <!-- long box -->
    <limit lower="-6" upper="6" effort="1.0" velocity="1.0"/>
  </joint>
  
  <link name="true_base_link"> <!-- real robot -->
    <inertial>
      <origin xyz="0 0 0" /> 
      <mass value="1.0" />
      <inertia  ixx="1.0" ixy="0.0"  ixz="0.0"  iyy="100.0"  iyz="0.0"  izz="1.0" />
    </inertial>
    <visual>
      <origin xyz="0 0 0"/>
      <geometry>
        <cylinder length="0.8" radius="0.14"/>
      </geometry>
      <material name="Blue">
        <color rgba="0 0 0.8 1"/>
      </material>
    </visual>   
    <collision>
      <origin xyz="0 0 0"/>
      <geometry>
        <cylinder length="0.8" radius="0.14"/>
      </geometry>
    </collision>
  </link>
</robot>
